<?xml version="1.0" ?>
<robot name="Capsule_robot" xmlns:xacro="http://www.ros.org/wiki/xacro">

<link name="base_link">
  <inertial>
    <origin xyz="8.44397401873128e-18 2.11099350468282e-18 0.01" rpy="0 0 0"/>
    <mass value="0.2642244262402339"/>
    <inertia ixx="2.3e-05" iyy="9.4e-05" izz="0.000103" ixy="0.0" iyz="0.0" ixz="0.0"/>
  </inertial>
  <visual>
    <origin xyz="0 0 0" rpy="0 0 0"/>
    <geometry>
      <mesh filename="file://$(find Capsule_robot_description)/meshes/base_link.stl" scale="0.001 0.001 0.001"/>
    </geometry>
    <material name="silver"/>
  </visual>
  <collision>
    <origin xyz="0 0 0" rpy="0 0 0"/>
    <geometry>
      <mesh filename="file://$(find Capsule_robot_description)/meshes/base_link.stl" scale="0.001 0.001 0.001"/>
    </geometry>
  </collision>
</link>

<link name="Capsule2_1">
  <inertial>
    <origin xyz="8.44397401873128e-18 0.02 0.0" rpy="0 0 0"/>
    <mass value="0.2642244262402339"/>
    <inertia ixx="2.3e-05" iyy="9.4e-05" izz="0.000103" ixy="0.0" iyz="0.0" ixz="0.0"/>
  </inertial>
  <visual>
    <origin xyz="-0.0 -0.02 -0.01" rpy="0 0 0"/>
    <geometry>
      <mesh filename="file://$(find Capsule_robot_description)/meshes/Capsule2_1.stl" scale="0.001 0.001 0.001"/>
    </geometry>
    <material name="silver"/>
  </visual>
  <collision>
    <origin xyz="-0.0 -0.02 -0.01" rpy="0 0 0"/>
    <geometry>
      <mesh filename="file://$(find Capsule_robot_description)/meshes/Capsule2_1.stl" scale="0.001 0.001 0.001"/>
    </geometry>
  </collision>
</link>

<link name="Capsule3_1">
  <inertial>
    <origin xyz="8.44397401873128e-18 0.020000000000000004 0.0" rpy="0 0 0"/>
    <mass value="0.2642244262402339"/>
    <inertia ixx="2.3e-05" iyy="9.4e-05" izz="0.000103" ixy="0.0" iyz="0.0" ixz="0.0"/>
  </inertial>
  <visual>
    <origin xyz="-0.0 -0.06 -0.01" rpy="0 0 0"/>
    <geometry>
      <mesh filename="file://$(find Capsule_robot_description)/meshes/Capsule3_1.stl" scale="0.001 0.001 0.001"/>
    </geometry>
    <material name="silver"/>
  </visual>
  <collision>
    <origin xyz="-0.0 -0.06 -0.01" rpy="0 0 0"/>
    <geometry>
      <mesh filename="file://$(find Capsule_robot_description)/meshes/Capsule3_1.stl" scale="0.001 0.001 0.001"/>
    </geometry>
  </collision>
</link>

<link name="Capsule4_1">
  <inertial>
    <origin xyz="8.44397401873128e-18 0.01999999999999999 0.0" rpy="0 0 0"/>
    <mass value="0.2642244262402339"/>
    <inertia ixx="2.3e-05" iyy="9.4e-05" izz="0.000103" ixy="0.0" iyz="0.0" ixz="0.0"/>
  </inertial>
  <visual>
    <origin xyz="-0.0 -0.1 -0.01" rpy="0 0 0"/>
    <geometry>
      <mesh filename="file://$(find Capsule_robot_description)/meshes/Capsule4_1.stl" scale="0.001 0.001 0.001"/>
    </geometry>
    <material name="silver"/>
  </visual>
  <collision>
    <origin xyz="-0.0 -0.1 -0.01" rpy="0 0 0"/>
    <geometry>
      <mesh filename="file://$(find Capsule_robot_description)/meshes/Capsule4_1.stl" scale="0.001 0.001 0.001"/>
    </geometry>
  </collision>
</link>

<link name="Capsule5_1">
  <inertial>
    <origin xyz="8.44397401873128e-18 0.01999999999999999 0.0" rpy="0 0 0"/>
    <mass value="0.2642244262402339"/>
    <inertia ixx="2.3e-05" iyy="9.4e-05" izz="0.000103" ixy="0.0" iyz="0.0" ixz="0.0"/>
  </inertial>
  <visual>
    <origin xyz="-0.0 -0.14 -0.01" rpy="0 0 0"/>
    <geometry>
      <mesh filename="file://$(find Capsule_robot_description)/meshes/Capsule5_1.stl" scale="0.001 0.001 0.001"/>
    </geometry>
    <material name="silver"/>
  </visual>
  <collision>
    <origin xyz="-0.0 -0.14 -0.01" rpy="0 0 0"/>
    <geometry>
      <mesh filename="file://$(find Capsule_robot_description)/meshes/Capsule5_1.stl" scale="0.001 0.001 0.001"/>
    </geometry>
  </collision>
</link>

<link name="Capsule6_1">
  <inertial>
    <origin xyz="8.44397401873128e-18 0.020000000000000018 0.0" rpy="0 0 0"/>
    <mass value="0.2642244262402339"/>
    <inertia ixx="2.3e-05" iyy="9.4e-05" izz="0.000103" ixy="0.0" iyz="0.0" ixz="0.0"/>
  </inertial>
  <visual>
    <origin xyz="-0.0 -0.18 -0.01" rpy="0 0 0"/>
    <geometry>
      <mesh filename="file://$(find Capsule_robot_description)/meshes/Capsule6_1.stl" scale="0.001 0.001 0.001"/>
    </geometry>
    <material name="silver"/>
  </visual>
  <collision>
    <origin xyz="-0.0 -0.18 -0.01" rpy="0 0 0"/>
    <geometry>
      <mesh filename="file://$(find Capsule_robot_description)/meshes/Capsule6_1.stl" scale="0.001 0.001 0.001"/>
    </geometry>
  </collision>
</link>

<link name="Capsule7_1">
  <inertial>
    <origin xyz="8.44397401873128e-18 0.01999999999999999 0.0" rpy="0 0 0"/>
    <mass value="0.2642244262402339"/>
    <inertia ixx="2.3e-05" iyy="9.4e-05" izz="0.000103" ixy="0.0" iyz="0.0" ixz="0.0"/>
  </inertial>
  <visual>
    <origin xyz="-0.0 -0.22 -0.01" rpy="0 0 0"/>
    <geometry>
      <mesh filename="file://$(find Capsule_robot_description)/meshes/Capsule7_1.stl" scale="0.001 0.001 0.001"/>
    </geometry>
    <material name="silver"/>
  </visual>
  <collision>
    <origin xyz="-0.0 -0.22 -0.01" rpy="0 0 0"/>
    <geometry>
      <mesh filename="file://$(find Capsule_robot_description)/meshes/Capsule7_1.stl" scale="0.001 0.001 0.001"/>
    </geometry>
  </collision>
</link>

<link name="Capsule8_1">
  <inertial>
    <origin xyz="8.44397401873128e-18 0.020000000000000018 0.0" rpy="0 0 0"/>
    <mass value="0.2642244262402339"/>
    <inertia ixx="2.3e-05" iyy="9.4e-05" izz="0.000103" ixy="0.0" iyz="0.0" ixz="0.0"/>
  </inertial>
  <visual>
    <origin xyz="-0.0 -0.26 -0.01" rpy="0 0 0"/>
    <geometry>
      <mesh filename="file://$(find Capsule_robot_description)/meshes/Capsule8_1.stl" scale="0.001 0.001 0.001"/>
    </geometry>
    <material name="silver"/>
  </visual>
  <collision>
    <origin xyz="-0.0 -0.26 -0.01" rpy="0 0 0"/>
    <geometry>
      <mesh filename="file://$(find Capsule_robot_description)/meshes/Capsule8_1.stl" scale="0.001 0.001 0.001"/>
    </geometry>
  </collision>
</link>

<link name="Capsule9_1">
  <inertial>
    <origin xyz="8.44397401873128e-18 0.020000000000000018 0.0" rpy="0 0 0"/>
    <mass value="0.2642244262402339"/>
    <inertia ixx="2.3e-05" iyy="9.4e-05" izz="0.000103" ixy="0.0" iyz="0.0" ixz="0.0"/>
  </inertial>
  <visual>
    <origin xyz="-0.0 -0.3 -0.01" rpy="0 0 0"/>
    <geometry>
      <mesh filename="file://$(find Capsule_robot_description)/meshes/Capsule9_1.stl" scale="0.001 0.001 0.001"/>
    </geometry>
    <material name="silver"/>
  </visual>
  <collision>
    <origin xyz="-0.0 -0.3 -0.01" rpy="0 0 0"/>
    <geometry>
      <mesh filename="file://$(find Capsule_robot_description)/meshes/Capsule9_1.stl" scale="0.001 0.001 0.001"/>
    </geometry>
  </collision>
</link>

<link name="Capsule10_1">
  <inertial>
    <origin xyz="8.44397401873128e-18 0.019999999999999962 0.0" rpy="0 0 0"/>
    <mass value="0.2642244262402339"/>
    <inertia ixx="2.3e-05" iyy="9.4e-05" izz="0.000103" ixy="0.0" iyz="0.0" ixz="0.0"/>
  </inertial>
  <visual>
    <origin xyz="-0.0 -0.34 -0.01" rpy="0 0 0"/>
    <geometry>
      <mesh filename="file://$(find Capsule_robot_description)/meshes/Capsule10_1.stl" scale="0.001 0.001 0.001"/>
    </geometry>
    <material name="silver"/>
  </visual>
  <collision>
    <origin xyz="-0.0 -0.34 -0.01" rpy="0 0 0"/>
    <geometry>
      <mesh filename="file://$(find Capsule_robot_description)/meshes/Capsule10_1.stl" scale="0.001 0.001 0.001"/>
    </geometry>
  </collision>
</link>

<joint name="Revolute 1" type="continuous">
  <origin xyz="0.0 0.02 0.01" rpy="0 0 0"/>
  <parent link="base_link"/>
  <child link="Capsule2_1"/>
  <axis xyz="0.0 0.0 -1.0"/>
</joint>

<joint name="Revolute 2" type="continuous">
  <origin xyz="0.0 0.04 0.0" rpy="0 0 0"/>
  <parent link="Capsule2_1"/>
  <child link="Capsule3_1"/>
  <axis xyz="0.0 0.0 -1.0"/>
</joint>

<joint name="Revolute 3" type="continuous">
  <origin xyz="0.0 0.04 0.0" rpy="0 0 0"/>
  <parent link="Capsule3_1"/>
  <child link="Capsule4_1"/>
  <axis xyz="0.0 0.0 -1.0"/>
</joint>

<joint name="Revolute 4" type="continuous">
  <origin xyz="0.0 0.04 0.0" rpy="0 0 0"/>
  <parent link="Capsule4_1"/>
  <child link="Capsule5_1"/>
  <axis xyz="0.0 0.0 -1.0"/>
</joint>

<joint name="Revolute 5" type="continuous">
  <origin xyz="0.0 0.04 0.0" rpy="0 0 0"/>
  <parent link="Capsule5_1"/>
  <child link="Capsule6_1"/>
  <axis xyz="0.0 0.0 -1.0"/>
</joint>

<joint name="Revolute 6" type="continuous">
  <origin xyz="0.0 0.04 0.0" rpy="0 0 0"/>
  <parent link="Capsule6_1"/>
  <child link="Capsule7_1"/>
  <axis xyz="0.0 0.0 -1.0"/>
</joint>

<joint name="Revolute 7" type="continuous">
  <origin xyz="0.0 0.04 0.0" rpy="0 0 0"/>
  <parent link="Capsule7_1"/>
  <child link="Capsule8_1"/>
  <axis xyz="0.0 0.0 -1.0"/>
</joint>

<joint name="Revolute 8" type="continuous">
  <origin xyz="0.0 0.04 0.0" rpy="0 0 0"/>
  <parent link="Capsule8_1"/>
  <child link="Capsule9_1"/>
  <axis xyz="0.0 0.0 -1.0"/>
</joint>

<joint name="Revolute 9" type="continuous">
  <origin xyz="0.0 0.04 0.0" rpy="0 0 0"/>
  <parent link="Capsule9_1"/>
  <child link="Capsule10_1"/>
  <axis xyz="0.0 0.0 -1.0"/>
</joint>

</robot>
